<?xml version="1.0" ?>
<robot name="Arm" xmlns:xacro="http://www.ros.org/wiki/xacro">

<xacro:include filename="$(find Arm_description)/urdf/materials.xacro" />
<xacro:include filename="$(find Arm_description)/urdf/Arm.trans" />
<xacro:include filename="$(find Arm_description)/urdf/Arm.gazebo" />
<link name="base_link">
  <inertial>
    <origin xyz="1.8767382473866447e-07 0.004999028053678853 1.138492838353351e-07" rpy="0 0 0"/>
    <mass value="0.2967963353905997"/>
    <inertia ixx="9.5e-05" iyy="0.000185" izz="9.5e-05" ixy="0.0" iyz="-0.0" ixz="0.0"/>
  </inertial>
  <visual>
    <origin xyz="0 0 0" rpy="0 0 0"/>
    <geometry>
      <mesh filename="package://Arm_description/meshes/base_link.stl" scale="0.001 0.001 0.001"/>
    </geometry>
    <material name="silver"/>
  </visual>
  <collision>
    <origin xyz="0 0 0" rpy="0 0 0"/>
    <geometry>
      <mesh filename="package://Arm_description/meshes/base_link.stl" scale="0.001 0.001 0.001"/>
    </geometry>
  </collision>
</link>

<link name="U_Joint_v4_1">
  <inertial>
    <origin xyz="0.0001002547826001979 0.01576223710657869 -2.223025061779516e-05" rpy="0 0 0"/>
    <mass value="0.12482744903626318"/>
    <inertia ixx="3.3e-05" iyy="4.2e-05" izz="5.3e-05" ixy="-0.0" iyz="0.0" ixz="5e-06"/>
  </inertial>
  <visual>
    <origin xyz="-0.0 -0.01 -0.0" rpy="0 0 0"/>
    <geometry>
      <mesh filename="package://Arm_description/meshes/U_Joint_v4_1.stl" scale="0.001 0.001 0.001"/>
    </geometry>
    <material name="silver"/>
  </visual>
  <collision>
    <origin xyz="-0.0 -0.01 -0.0" rpy="0 0 0"/>
    <geometry>
      <mesh filename="package://Arm_description/meshes/U_Joint_v4_1.stl" scale="0.001 0.001 0.001"/>
    </geometry>
  </collision>
</link>

<link name="Rotation_Pin_v8_1">
  <inertial>
    <origin xyz="-3.49524931191432e-06 -0.0006058825438886462 -1.1173475584451635e-06" rpy="0 0 0"/>
    <mass value="0.023921840281251883"/>
    <inertia ixx="1e-06" iyy="1e-06" izz="1e-06" ixy="-0.0" iyz="-0.0" ixz="-0.0"/>
  </inertial>
  <visual>
    <origin xyz="0.0 -0.015 -0.0" rpy="0 0 0"/>
    <geometry>
      <mesh filename="package://Arm_description/meshes/Rotation_Pin_v8_1.stl" scale="0.001 0.001 0.001"/>
    </geometry>
    <material name="silver"/>
  </visual>
  <collision>
    <origin xyz="0.0 -0.015 -0.0" rpy="0 0 0"/>
    <geometry>
      <mesh filename="package://Arm_description/meshes/Rotation_Pin_v8_1.stl" scale="0.001 0.001 0.001"/>
    </geometry>
  </collision>
</link>

<link name="U_Joint_v4__1__1">
  <inertial>
    <origin xyz="-0.00467309810248912 0.002355564474227939 -0.014868165099041902" rpy="0 0 0"/>
    <mass value="0.12482744903626318"/>
    <inertia ixx="4.8e-05" iyy="3.7e-05" izz="4.3e-05" ixy="-9e-06" iyz="2e-06" ixz="-3e-06"/>
  </inertial>
  <visual>
    <origin xyz="0.012105 -0.166153 0.199184" rpy="0 0 0"/>
    <geometry>
      <mesh filename="package://Arm_description/meshes/U_Joint_v4__1__1.stl" scale="0.001 0.001 0.001"/>
    </geometry>
    <material name="silver"/>
  </visual>
  <collision>
    <origin xyz="0.012105 -0.166153 0.199184" rpy="0 0 0"/>
    <geometry>
      <mesh filename="package://Arm_description/meshes/U_Joint_v4__1__1.stl" scale="0.001 0.001 0.001"/>
    </geometry>
  </collision>
</link>

<link name="U_joint_Pin_v9_1">
  <inertial>
    <origin xyz="0.009578409593339523 1.2516205410567638e-06 -0.0021184041965689455" rpy="0 0 0"/>
    <mass value="0.03643052624181974"/>
    <inertia ixx="2e-06" iyy="8e-06" izz="8e-06" ixy="-0.0" iyz="0.0" ixz="1e-06"/>
  </inertial>
  <visual>
    <origin xyz="0.019771 -0.04 -0.004377" rpy="0 0 0"/>
    <geometry>
      <mesh filename="package://Arm_description/meshes/U_joint_Pin_v9_1.stl" scale="0.001 0.001 0.001"/>
    </geometry>
    <material name="silver"/>
  </visual>
  <collision>
    <origin xyz="0.019771 -0.04 -0.004377" rpy="0 0 0"/>
    <geometry>
      <mesh filename="package://Arm_description/meshes/U_joint_Pin_v9_1.stl" scale="0.001 0.001 0.001"/>
    </geometry>
  </collision>
</link>

<link name="End_Effector_v4_1">
  <inertial>
    <origin xyz="-0.011378321973177709 -0.010888656891483078 -0.006484828688145844" rpy="0 0 0"/>
    <mass value="0.25961074815803725"/>
    <inertia ixx="5.3e-05" iyy="5.3e-05" izz="4.8e-05" ixy="-0.0" iyz="3e-06" ixz="-6e-06"/>
  </inertial>
  <visual>
    <origin xyz="0.013481 -0.184128 0.227601" rpy="0 0 0"/>
    <geometry>
      <mesh filename="package://Arm_description/meshes/End_Effector_v4_1.stl" scale="0.001 0.001 0.001"/>
    </geometry>
    <material name="silver"/>
  </visual>
  <collision>
    <origin xyz="0.013481 -0.184128 0.227601" rpy="0 0 0"/>
    <geometry>
      <mesh filename="package://Arm_description/meshes/End_Effector_v4_1.stl" scale="0.001 0.001 0.001"/>
    </geometry>
  </collision>
</link>

<link name="U_joint_Pin_v9__1__1">
  <inertial>
    <origin xyz="-0.004772347161610532 -0.008570675381614684 7.408771581568496e-05" rpy="0 0 0"/>
    <mass value="0.03643052624181974"/>
    <inertia ixx="6e-06" iyy="3e-06" izz="8e-06" ixy="-3e-06" iyz="0.0" ixz="0.0"/>
  </inertial>
  <visual>
    <origin xyz="0.011048 -0.188496 0.227639" rpy="0 0 0"/>
    <geometry>
      <mesh filename="package://Arm_description/meshes/U_joint_Pin_v9__1__1.stl" scale="0.001 0.001 0.001"/>
    </geometry>
    <material name="silver"/>
  </visual>
  <collision>
    <origin xyz="0.011048 -0.188496 0.227639" rpy="0 0 0"/>
    <geometry>
      <mesh filename="package://Arm_description/meshes/U_joint_Pin_v9__1__1.stl" scale="0.001 0.001 0.001"/>
    </geometry>
  </collision>
</link>

<link name="Spit_Lower_Link_Bottom_v4_1">
  <inertial>
    <origin xyz="-0.01857337480612438 0.03224156534920129 -0.015011704174528474" rpy="0 0 0"/>
    <mass value="0.9607992978507599"/>
    <inertia ixx="0.000981" iyy="0.00037" izz="0.00086" ixy="7.5e-05" iyz="0.000337" ixz="-2.8e-05"/>
  </inertial>
  <visual>
    <origin xyz="-0.013825 -0.05 0.006437" rpy="0 0 0"/>
    <geometry>
      <mesh filename="package://Arm_description/meshes/Spit_Lower_Link_Bottom_v4_1.stl" scale="0.001 0.001 0.001"/>
    </geometry>
    <material name="silver"/>
  </visual>
  <collision>
    <origin xyz="-0.013825 -0.05 0.006437" rpy="0 0 0"/>
    <geometry>
      <mesh filename="package://Arm_description/meshes/Spit_Lower_Link_Bottom_v4_1.stl" scale="0.001 0.001 0.001"/>
    </geometry>
  </collision>
</link>

<link name="Spit_Lower_Link_Top_v5_1">
  <inertial>
    <origin xyz="-0.0005043595164674845 0.013253018119640136 -0.0070704207416799475" rpy="0 0 0"/>
    <mass value="0.26562783764071035"/>
    <inertia ixx="4.3e-05" iyy="6.3e-05" izz="6.1e-05" ixy="-1e-06" iyz="0.0" ixz="7e-06"/>
  </inertial>
  <visual>
    <origin xyz="0.009973 -0.12872 0.045049" rpy="0 0 0"/>
    <geometry>
      <mesh filename="package://Arm_description/meshes/Spit_Lower_Link_Top_v5_1.stl" scale="0.001 0.001 0.001"/>
    </geometry>
    <material name="silver"/>
  </visual>
  <collision>
    <origin xyz="0.009973 -0.12872 0.045049" rpy="0 0 0"/>
    <geometry>
      <mesh filename="package://Arm_description/meshes/Spit_Lower_Link_Top_v5_1.stl" scale="0.001 0.001 0.001"/>
    </geometry>
  </collision>
</link>

<link name="Upper_Link_v13_1">
  <inertial>
    <origin xyz="-0.0006924110201292372 0.009333525901086964 -0.0683637085783005" rpy="0 0 0"/>
    <mass value="1.3718003207169909"/>
    <inertia ixx="0.002426" iyy="0.002626" izz="0.000522" ixy="0.000108" iyz="0.00035" ixz="-0.000618"/>
  </inertial>
  <visual>
    <origin xyz="-0.00992 -0.145378 0.061041" rpy="0 0 0"/>
    <geometry>
      <mesh filename="package://Arm_description/meshes/Upper_Link_v13_1.stl" scale="0.001 0.001 0.001"/>
    </geometry>
    <material name="silver"/>
  </visual>
  <collision>
    <origin xyz="-0.00992 -0.145378 0.061041" rpy="0 0 0"/>
    <geometry>
      <mesh filename="package://Arm_description/meshes/Upper_Link_v13_1.stl" scale="0.001 0.001 0.001"/>
    </geometry>
  </collision>
</link>

<link name="Arm_Pin_v8_1">
  <inertial>
    <origin xyz="-0.01252298553634533 0.000620731896416038 0.003997231201997506" rpy="0 0 0"/>
    <mass value="0.04039333046444542"/>
    <inertia ixx="2e-06" iyy="1.2e-05" izz="1.1e-05" ixy="0.0" iyz="-0.0" ixz="3e-06"/>
  </inertial>
  <visual>
    <origin xyz="-0.043227 -0.143727 0.071667" rpy="0 0 0"/>
    <geometry>
      <mesh filename="package://Arm_description/meshes/Arm_Pin_v8_1.stl" scale="0.001 0.001 0.001"/>
    </geometry>
    <material name="silver"/>
  </visual>
  <collision>
    <origin xyz="-0.043227 -0.143727 0.071667" rpy="0 0 0"/>
    <geometry>
      <mesh filename="package://Arm_description/meshes/Arm_Pin_v8_1.stl" scale="0.001 0.001 0.001"/>
    </geometry>
  </collision>
</link>

<link name="Arm_Rotation_Pin_v3_1">
  <inertial>
    <origin xyz="0.0009335353294862118 -0.008324876082566296 0.004226406798621372" rpy="0 0 0"/>
    <mass value="0.03590735306331089"/>
    <inertia ixx="7e-06" iyy="3e-06" izz="6e-06" ixy="1e-06" iyz="2e-06" ixz="-0.0"/>
  </inertial>
  <visual>
    <origin xyz="0.012965 -0.155335 0.058563" rpy="0 0 0"/>
    <geometry>
      <mesh filename="package://Arm_description/meshes/Arm_Rotation_Pin_v3_1.stl" scale="0.001 0.001 0.001"/>
    </geometry>
    <material name="silver"/>
  </visual>
  <collision>
    <origin xyz="0.012965 -0.155335 0.058563" rpy="0 0 0"/>
    <geometry>
      <mesh filename="package://Arm_description/meshes/Arm_Rotation_Pin_v3_1.stl" scale="0.001 0.001 0.001"/>
    </geometry>
  </collision>
</link>

<joint name="base1" type="revolute">
  <origin xyz="0.0 0.01 0.0" rpy="0 0 0"/>
  <parent link="base_link"/>
  <child link="U_Joint_v4_1"/>
  <axis xyz="0.0 1.0 0.0"/>
  <limit upper="1.570796" lower="-1.570796" effort="100" velocity="100"/>
</joint>

<joint name="Rigid 2" type="fixed">
  <origin xyz="-0.0 0.005 0.0" rpy="0 0 0"/>
  <parent link="U_Joint_v4_1"/>
  <child link="Rotation_Pin_v8_1"/>
</joint>

<joint name="wrist" type="continuous">
  <origin xyz="-0.022025 0.020775 -0.138143" rpy="0 0 0"/>
  <parent link="Upper_Link_v13_1"/>
  <child link="U_Joint_v4__1__1"/>
  <axis xyz="-0.293271 0.155132 -0.943359"/>
</joint>

<joint name="base pin" type="continuous">
  <origin xyz="-0.019771 0.03 0.004377" rpy="0 0 0"/>
  <parent link="U_Joint_v4_1"/>
  <child link="U_joint_Pin_v9_1"/>
  <axis xyz="0.97636 0.0 -0.21615"/>
</joint>

<joint name="fingers" type="revolute">
  <origin xyz="-0.001376 0.017975 -0.028417" rpy="0 0 0"/>
  <parent link="U_Joint_v4__1__1"/>
  <child link="End_Effector_v4_1"/>
  <axis xyz="0.486715 0.873527 -0.007661"/>
  <limit upper="3.141593" lower="0.0" effort="100" velocity="100"/>
</joint>

<joint name="wrist_pin" type="continuous">
  <origin xyz="0.001057 0.022343 -0.028455" rpy="0 0 0"/>
  <parent link="U_Joint_v4__1__1"/>
  <child link="U_joint_Pin_v9__1__1"/>
  <axis xyz="-0.486715 -0.873527 0.007661"/>
</joint>

<joint name="shoulder " type="revolute">
  <origin xyz="0.013825 0.04 -0.006437" rpy="0 0 0"/>
  <parent link="U_Joint_v4_1"/>
  <child link="Spit_Lower_Link_Bottom_v4_1"/>
  <axis xyz="-0.97636 -0.0 0.21615"/>
  <limit upper="-1.570796" lower="-4.712389" effort="100" velocity="100"/>
</joint>

<joint name="elbow1" type="continuous">
  <origin xyz="-0.023798 0.07872 -0.038612" rpy="0 0 0"/>
  <parent link="Spit_Lower_Link_Bottom_v4_1"/>
  <child link="Spit_Lower_Link_Top_v5_1"/>
  <axis xyz="-0.09973 0.887195 -0.450487"/>
</joint>

<joint name="elbow2" type="continuous">
  <origin xyz="0.019893 0.016658 -0.015992" rpy="0 0 0"/>
  <parent link="Spit_Lower_Link_Top_v5_1"/>
  <child link="Upper_Link_v13_1"/>
  <axis xyz="-0.95163 0.047185 0.303602"/>
</joint>

<joint name="Rigid 13" type="fixed">
  <origin xyz="0.033307 -0.001651 -0.010626" rpy="0 0 0"/>
  <parent link="Upper_Link_v13_1"/>
  <child link="Arm_Pin_v8_1"/>
</joint>

<joint name="Rigid 14" type="fixed">
  <origin xyz="-0.002992 0.026615 -0.013514" rpy="0 0 0"/>
  <parent link="Spit_Lower_Link_Top_v5_1"/>
  <child link="Arm_Rotation_Pin_v3_1"/>
</joint>

</robot>
